Workbook

Sheet README
A1: RevisionGrade Project Management Roadmap Tracker
A2: Generated: March 19, 2026
A3: Owner: Mike Meraw
A4: Total Items: 44 work items across 6 phases (0-5)
A5: Canon: Volumes I-V fully integrated (77 doctrine units referenced)
A6: ---
A8: Executive Summary
A10: Status Overview
A11: Completed: 8 items (1.1, 1.2, 2.1, 2.2, 2.3, 2.4, 2.5, 2.6)
A12: In Progress: 1 item (2.7)
A13: Next: 7 items
A14: Planned: 16 items
... A86: + 9 supporting/variant documents (txt, md formats)

Sheet Overview
B2: RevisionGrade — Product Roadmap
B3: Upload → Evaluation → Revision → Packaging → StoryGate → Agents
B4: Generated: March 19, 2026 | Owner: Mike Meraw | Canon: Volumes I-V integrated
B6: STATUS SUMMARY
B8: Completed | C8: In Progress | D8: Next | E8: Planned | F8: Future | G8: Total Items
B9: =COUNTIF(Roadmap!F:F,"Completed") | C9: =COUNTIF(Roadmap!F:F,"In Progress") | D9: =COUNTIF(Roadmap!F:F,"Next") | E9: =COUNTIF(Roadmap!F:F,"Planned") | F9: =COUNTIF(Roadmap!F:F,"Future") | G9: =COUNTA(Roadmap!F2:F100)
B12: PHASE PROGRESS
B14: Phase | C14: Name | D14: Items | E14: Completed | F14: % Done
B15: 0 | C15: Canon Integration & Authority | D15: =COUNTIF(Roadmap!B:B,0) | E15: =COUNTIFS(Roadmap!B:B,0,Roadmap!F:F,"Completed") | F15: =IF(D15=0,0,E15/D15)
B16: 1 | C16: Foundation & Governance | D16: =COUNTIF(Roadmap!B:B,1) | E16: =COUNTIFS(Roadmap!B:B,1,Roadmap!F:F,"Completed") | F16: =IF(D16=0,0,E16/D16)
B17: 2 | C17: Evaluation Quality & Credibility | D17: =COUNTIF(Roadmap!B:B,2) | E17: =COUNTIFS(Roadmap!B:B,2,Roadmap!F:F,"Completed") | F17: =IF(D17=0,0,E17/D17)
B18: 3 | C18: Action Loop: Revision & WAVE | D18: =COUNTIF(Roadmap!B:B,3) | E18: =COUNTIFS(Roadmap!B:B,3,Roadmap!F:F,"Completed") | F18: =IF(D18=0,0,E18/D18)
B19: 4 | C19: Conversion & Packaging | D19: =COUNTIF(Roadmap!B:B,4) | E19: =COUNTIFS(Roadmap!B:B,4,Roadmap!F:F,"Completed") | F19: =IF(D19=0,0,E19/D19)
B20: 5 | C20: Dashboards, Analytics & Platform | D20: =COUNTIF(Roadmap!B:B,5) | E20: =COUNTIFS(Roadmap!B:B,5,Roadmap!F:F,"Completed") | F20: =IF(D20=0,0,E20/D20)
B23: SHEET INDEX
B25: Roadmap | C25: Full sequential task tracker with all PM fields
B26: Immediate Priorities | C26: The 'next three' critical deliverables
B27: Sprint 0 (Phase 2) | C27: Governed execution board: 15 atomic subtasks for 2.1-2.5 with Success/Test/Artifact
B28: Canon Reference | C28: Authority chain, numeric constants, governance rules from Volumes I-V

Sheet Roadmap
A1: # | B1: Phase | C1: ID | D1: Task | E1: Description / Scope | F1: Status | G1: Priority | H1: Why This Step | I1: How to Execute | J1: Where (Codebase) | K1: Owner | L1: LOE (hrs) | M1: Dependencies | N1: Success Criteria | O1: Test Method | P1: Priority Lock | Q1: Notes | R1: Canon Reference
A2: 0 | B2: 0 | C2: 0.1 | D2: Canon Registry Binding (Runtime) | F2: Next | G2: P0 | H2: Canon authority is documented but not yet wired into execution. Canon IDs, doctrine precedence rules, and version tracking must be loadable at runtime so pipeline steps can validate against the living canon — not a snapshot. | I2: Build canon registry module: load all 77 doctrine IDs from Canon Doctrine Registry. Define precedence chain (Canon III → Vol IV → Registry → RCAM → Vol II → Vol II-A → Vol I → Vol III → Vol V). Version-stamp every canon load. Fail if canon version is stale or missing. | J2: lib/canon/registry.ts | K2: Mike + Copilot | L2: 6-8 | M2: 1.1 | N2: Canon registry loads all 77 doctrine units at runtime. Precedence chain enforced. Version tracking active. Stale/missing canon fails closed. | O2: Load registry — verify 77 doctrine IDs present. Remove one doctrine — verify load fails. Change version — verify staleness detected. | P2: Yes | Q2: This is NOT the static Canon Reference sheet — this is the runtime enforcement mechanism. Must load before any pipeline step executes. | R2: Canon Doctrine Registry (77 units, 6 governance rules), RCAM v2.0 (24 source docs, 5 matrix rules), Canon III (8 governing laws)
A3: 0 | B3: 0 | C3: 0.2 | D3: Lessons Learned Canon Integration | F3: Next | G3: P1 | H3: Canon III defines 8 governing laws (Lessons I:1-I:8) that represent hard-won operational truths. These are not just documentation — they must become detection patterns, validation rules, and failure conditions in the pipeline. | I3: Convert each Canon III lesson into an enforceable rule: 'Blur not multiplicity' → diagnostic detection rule. 'Authority transfer clarity' → pipeline validation check. 'Stalled scene' → environmental echo chain detector (flag 3+ consecutive atmospheric openings). 'Over-editing risk' → WAVE revision boundary check. 'Adversarial testing required' (I:5) → QA harness requirement. | J3: lib/canon/lessons.ts, lib/validation/ | K3: Mike + Copilot | L3: 8-12 | M3: 0.1 | N3: All 8 Canon III lessons have corresponding detection/validation rules. Rules fire during evaluation pipeline. False positive rate <5% on known-good manuscripts. | O3: Submit manuscript with known stalled-scene pattern — flagged. Submit with blur pattern — flagged. Submit clean manuscript — no false flags on known-good patterns. | P3: Yes | Q3: Lesson I:5 (resistance reveals structure) directly mandates adversarial testing as a governance requirement — feeds into 5.12 QA Corpus. | R3: Canon III Lessons I:1-I:8 (8 governing laws), Vol II (diagnostic patterns: Environmental Echo Chain, Scene Entry Scan)
A4: 0 | B4: 0 | C4: 0.3 | D4: Governance Enforcement Injection Map | F4: Next | G4: P1 | H4: Governance rules exist (Vol III, IV) but the roadmap doesn't show WHERE each rule applies in the pipeline. Without explicit injection points, governance is passive documentation, not active enforcement. This is the bridging layer. | I4: Define injection points for every pipeline stage: (1) Ingestion: format validation, worktype detection. (2) Evaluation: Canon Gate (Pass 1.5), two-AI independence, score thresholds. (3) Synthesis: convergence validation, divergence logging. (4) Revision: WAVE eligibility gate, structural-fail block. (5) Output: Trusted Path certification, audit trail completeness. (6) Artifact generation: non-repudiation, hash chain. Map each Vol IV governance rule to its exact pipeline stage. | J4: docs/governance/enforcement-map.md, lib/governance/ | K4: Mike + Copilot | L4: 4-6 | M4: 0.1 | N4: Every Vol IV governance rule mapped to specific pipeline stage. Every pipeline stage has defined governance checks. No 'governance-free' pipeline stages exist. | O4: Walk through complete pipeline execution — verify governance check fires at every stage. Attempt to skip governance check — blocked. | P4: Yes | Q4: This is the design artifact, not the implementation. Implementation happens in 2.9 (Canon Gate), 5.13 (Audit Spine), 5.14 (Canon Protection). Cross-ref: 0.4 (Canon Guard Runtime) = 2.9 + 5.14 combined. 0.5 (Audit & Proof Layer) = 5.13. | R4: Vol IV (7 canon protection systems), Vol III Governance (5 non-negotiable platform doctrines), Vol V (AEP 6-step flow with audit events per step)
A5: 1 | B5: 1 | C5: 1.1 | D5: Canon, Contracts & CI | F5: Completed | G5: P0 | H5: Without canonical naming, schema governance, and CI gates, every later feature risks schema drift, broken routing, and non-auditable output. | I5: Gate pattern (A5, A6...): spec → implementation → CI proof → closure doc. Versioned artifacts (evaluationresultv1, trajectorysignalv1), JOBCONTRACT, governance docs. | J5: CI / Artifacts | K5: Mike + Copilot | L5: 0 | M5: — | N5: Deterministic, immutable outputs; all artifacts versioned and governed. | P5: Yes | Q5: Stage 2 baseline complete. 5-volume governance docs in place. | R5: Vol III (Platform Governance), Vol IV (AI Governance), Canon Doctrine Registry, RCAM v2.0, Canon III Lessons I:1-I:8
A6: 2 | B6: 1 | C6: 1.2 | D6: Flow 1 Evaluation Loop (Gate A5) | F6: Completed | G6: P0 | H6: Proved 'manuscript in, authoritative report out' end-to-end. This is the investable spine of the product. | I6: Single canonical artifact per job, no recompute on read, idempotent reruns, ownership enforced. Report page reads only stored artifacts. | J6: Core Engine / Report UI | K6: Mike + Copilot | L6: 0 | M6: 1.1 | N6: Manuscript in → canonical Phase 2 artifact out → report page that reads only stored artifacts. | P6: Yes | Q6: Gate A5 closed. | R6: Vol II-A (Operational Schema §evaluation envelope), Vol III (Tools §EvaluationResultV1), Vol V (AEP Steps 1-3)
A7: 3 | B7: 2 | C7: 2.1 | D7: Anchor Metadata System | F7: Completed | G7: P0 | H7: Eliminate apply ambiguity. Every proposal must have precise start/end/context fields so the system knows exactly where to apply changes. | I7: Add start, end, and context fields to change_proposals. Validate 100% of proposals have valid anchors. | J7: change_proposals | K7: Mike + Copilot | L7: 4-6 | M7: 1.2 | N7: 100% of change_proposals contain valid start_offset, end_offset, and before_context/after_context. 0 nulls accepted. 0 partial anchors. Validation rejects malformed anchors at insert time. | O7: SQL null check: SELECT COUNT(*) FROM change_proposals WHERE start_offset IS NULL OR end_offset IS NULL → must return 0. Sample 100 proposals → confirm exact alignment with source text. Attempt 5 invalid inserts → all rejected. | P7: Yes | Q7: CODE: Complete. TESTS: Verified (4/4 pass). DB VERIFICATION: PASSED (2026-03-18). 6-Gate verification executed against target DB (xtumxjnzdswuumndcbwc): Gate 1 (migration presence) PASSED. Gate 2 (schema completeness — 3 anchor cols) PASSED. Gate 3 (index presence — 2 anchor indexes) PASSED. Gate 4 (core Stage 2 tables) PASSED. Gate 5 (RLS enabled on all 3 tables) PASSED. Gate 6 (anchor row integrity — deterministic slice contract) PASSED: 21 anchored rows verified, source_text.slice(start, end) === original_text for all rows. Data remediation applied: 2 manuscript_versions had empty raw_text (backfilled from file_url data URIs). 15 anchor offsets recomputed to align with decoded raw_text. apply.ts contract confirmed: normalizeForStrictMatch + fail-closed, no legacy text-search fallback for anchored proposals. GATE CLEARED: 2.2 may proceed. | R7: Vol III Tools (§ChangeProposal schema), Vol III Ops (§III.O4 Stage 2-3)
A8: 4 | B8: 2 | C8: 2.2 | D8: Proposal Extraction Contract | F8: Completed | G8: P0 | H8: Ensure exact anchors with zero whitespace drift or partial captures. The extraction contract is the bridge between evaluation output and revision input. | I8: Deterministic extraction contract: source_text.slice(start_offset, end_offset) must exactly reproduce anchor_text_normalized with zero ambiguity. No whitespace drift, no partial captures, no encoding differences. Validate every anchor against source text byte-for-byte. Handle unicode, em-dashes, smart quotes, and multi-byte characters. Extraction is purely mechanical — no inference, no fuzzy matching. | J8: Proposal logic | K8: Mike + Copilot | L8: 6-8 | M8: 2.1 | N8: source_text.slice(start_offset, end_offset) === anchor_text_normalized for 100% of proposals. 0 whitespace drift. 0 partial captures (every extraction includes complete sentence/clause boundaries). 0 encoding mismatches. Handles unicode, em-dashes, smart quotes. Extraction is deterministic and reproducible — same input always produces same output. | O8: Substring reconstruction test: reconstruct anchor from source using offsets → must equal original_text. Diff validation across full corpus (not samples): extracted_text === source_slice. Run extraction on 50+ proposals from 3 manuscripts → 0 byte-level differences. | P8: Yes | Q8: Phase 2.2 COMPLETED (2026-03-19). 21/21 tests green. validateExtractionContract enforced at proposal creation. No fallback. Fail-closed. | GATE: 2.1 DB verification passed (2026-03-18). 2.2 may proceed. Deterministic formula: source_text.slice(start_offset, end_offset) must exactly reproduce anchor_text_normalized. Output Artifacts: extraction module (lib/evaluation/proposals/extractProposals.ts), extraction diff report (CSV: proposal_id, source_text, extracted_text, match_status), coverage report (≥95% line coverage on extraction logic). | R8: Vol III Tools (§III.T4 extraction contract), Vol II-A (§evidence excerpt max 200 chars)
A9: 5 | B9: 2 | C9: 2.3 | D9: Location-Aware Apply | F9: Completed | G9: P0 | H9: Deterministic apply engine: given a valid anchor, the system must apply the change to exactly the right location every time. | I9: Offset + context validation. Character-level positioning with fallback matching. Idempotent apply logic. | J9: Finalize logic | K9: Mike + Copilot | L9: 8-12 | M9: 2.2 | N9: ≥99.5% correct placement on valid anchors. 0 incorrect placements (wrong location = critical failure). Idempotent: applying same proposal twice produces identical output. Handles multi-byte unicode correctly. | O9: Batch apply: run 500-1000 proposals through apply engine. Track: success, mismatch, failure type. Rerun consistency: re-run identical batch → outputs must be byte-identical. Edge cases: offset shifted by prior edit, context fallback, overlapping proposals, unicode stress test. | P9: Yes | Q9: THE CORE PRODUCT. The apply engine is the product — everything else is presentation. Difficulty: HARD. This is where determinism is either proven or breaks. Do NOT patch edge cases with hacks. Log everything, classify failures (2.4), refine determinism. Output Artifacts: applyEngine.ts, success rate report, test harness (tests/applyEngine/), CI integration. | R9: Vol V (AEP Step 3 — Apply), Vol III Ops (§III.O8 determinism requirement)
A10: 6 | B10: 2 | C10: 2.4 | D10: Failure Classification | F10: Completed | G10: P0 | H10: Every failure must be diagnosable. Unclassified failures are invisible failures — they erode trust and make debugging impossible. | I10: Enumerate failure codes for every apply path. Classify by type (anchor miss, conflict, parse error, etc.) and persist to revision_sessions. | J10: revision_sessions | K10: Mike + Copilot | L10: 4-6 | M10: 2.3 | N10: 100% of failures mapped to defined actionable codes (ANCHOR_MISS, ANCHOR_AMBIGUOUS, CONTEXT_MISMATCH, OFFSET_CONFLICT, PARSE_ERROR, APPLY_COLLISION). 0 'unknown' failures on reproducible scenarios. All failure types persisted in revision_sessions with failure_code, failure_detail, failure_timestamp. | O10: Force failure scenarios: bad anchor, ambiguous match, missing source, overlapping edits, corrupt input. Verify each produces correct failure_code + correct failure_message. Query: SELECT * FROM revision_sessions WHERE status='failed' AND failure_code IS NULL → must return 0 rows. | P10: Yes | Q10: COMPLETED at abe6146. Engine hardening: 10 suites/100 tests. Pack A (27 tests), Pack C (24 tests), Pack D (182/182 valid, 0 wrong-location), Pack F (100k soak: 0 unclassified, 0 wrong-location, 0 lost writes). Fail-closed malformed-candidate fix shipped. Operations docs spine published. | R10: Vol V (§V.11 reliability model, dead-letter), Vol IV (§IV.G4.3 violation severity classes)
A11: 7 | B11: 2 | C11: 2.5 | D11: Stage 2.5 Validation | F11: Completed | G11: P0 | H11: Verify that the entire anchor → extract → apply pipeline is deterministic. Repeat runs must produce identical outputs. | I11: Test harness: run the same manuscript through the pipeline N times. Compare outputs byte-for-byte. CI integration. | J11: CI / Test harness | K11: Mike | L11: 2-4 | M11: 2.4 | N11: Identical outputs every run across full test suite. | P11: No | Q11: COMPLETED at 48aa4c9 (2026-03-19). Deterministic matrix: 5 success cases (single, multi-proposal, literary prose, dialogue, multi-paragraph), 3 failure cases (PARSE_ERROR, ANCHOR_MISS, OFFSET_CONFLICT). 9/9 ingest, 9/9 extract, 9/9 validate, 9/9 apply. Repeated-run byte identity: true. 3 archived evidence runs. Closure doc published. | R11: Vol III Ops (§III.O8 determinism), Vol V (§V.11 idempotency), Canon III Lesson I:5 (resistance reveals structure)
A12: 8 | B12: 2 | C12: 2.6 | D12: A6 Report Credibility Layer | F12: Completed | G12: P1 | H12: A writer must see 'why 8.3?' in plain language before they'll trust anything more advanced. Score explanations, rubric breakdown, confidence, and provenance — all from persisted artifacts. | I12: Extend evaluationresultv1 content with rubric items and credibility block (no new tables). Render 'Why this score?' section in report UI (no recompute, artifact-only). | J12: Report UI / evaluationresultv1 | K12: Mike + Copilot | L12: 6-8 | M12: 1.2 | N12: Rubric breakdown, score explanations, confidence, and provenance visible on report. Zero recomputation on read. | O12: 4 unit tests (credibility, missing-refs, phantom-anchor, confidence-richness) + 1 artifact output test (JSON+MD write verification) + evidence run validation | P12: No | Q12: COMPLETED at 0b0b657, verified at 38d9c19, closure doc landed at 66b84e4 (2026-03-19). 6 modules: types.ts, buildA6Report.ts, confidence.ts, provenance.ts, validateA6Report.ts, writeA6Artifacts.ts. 5 tests: rubric+confidence+provenance, missing-evidence-refs, phantom-anchor, confidence-richness, artifact-output. Evidence: narrative_cohesion 8.5/10, tone_consistency 8.9/10, overall 8.7, confidence 0.9, 2 provenance entries, offsets [4,22) [43,86) consistent. All invariants pass. Closure doc: 214 lines on main, fully populated. | R12: Vol II (13 Criteria + diagnostic framework), Vol II-A (§WCS computation, eligibility gates), Vol III Ops (§score thresholds 50/60/65/80)
A13: 9 | B13: 2 | C13: 2.7 | D13: Evaluation Uplift (Pass 1-4, Dual Axis) | F13: In Progress | G13: P1 | H13: The psychological shift from 'grader' to 'trusted editor.' Dual-axis evaluation: Craft Execution + Editorial/Literary Insight, with quality guards that prevent generic or duplicated output. | I13: Multi-pass pipeline: structural → intent/genre → interpretive → synthesis. Guards: no duplicated recs vs summary, no generic recs (must anchor to character/scene/event), no pretending full coverage when partial. | J13: Evaluation pipeline | K13: Mike + Copilot | L13: 12-16 | M13: 2.6 | N13: Dual-axis scores. Zero generic recommendations. All recs anchored to specific text. Quality guards pass CI. | O13: 6 test suites: pass1, pass2, pass3, pipeline-e2e, pipeline-independence, quality-gate. 52 tests total. Pure parser tests + DI runner tests + deterministic quality gate. npm test -- tests/evaluation/pipeline/ --runInBand | P13: No | Q13: IN PROGRESS at a6f0492, 9ef8afe, c91f26c (2026-03-19). Pipeline scaffold implemented: Pass 1, Pass 2, Pass 3, orchestration runner, prompts, quality gate, and deterministic parser-level test seams. Jest/SWC mock-hoisting issue removed via dependency injection and pure parser tests. Pipeline suite green: 6 suites, 52 tests passing. | R13: Vol II (13 Criteria, 10 diagnostic patterns), Vol III Tools (§PASS1/PASS2/PASS3 prompts, temperatures 0.3/0.2), Vol IV (§multi-AI consensus)
A14: 10 | B14: 2 | C14: 2.8 | D14: Multi-Chunk Evaluation Synthesis | F14: Next | G14: P1 | H14: Core promise is 'whole-work editorial intelligence,' not 'first 10K words.' Must handle full manuscripts and screenplays via chunking with aggregate memory. | I14: Ensure 100% text coverage or explicit 'partial evaluation' labeling. Aggregate per-criterion signals across chunks into the 13-criterion rubric. Unified result artifact. | J14: Evaluation pipeline | K14: Mike + Copilot | L14: 10-14 | M14: 2.7 | N14: 100% coverage or explicit partial labeling. Unified rubric scores across all chunks. | P14: No | Q14: Must land before heavy product UX work. | R14: Vol V (§V.5 chunking architecture, whole-manuscript reconciliation)
A15: 11 | B15: 3 | C15: 3.1 | D15: State Machine (Session Lifecycle) | F15: Next | G15: P1 | H15: Explicit lifecycle for revision sessions. Without defined states and transitions, sessions can drift into invalid or unrecoverable states. | I15: Define lifecycle states (created → evaluating → proposing → applying → reviewing → closed). Enforce valid transitions. Persist state to revision_sessions. | J15: revision_sessions | K15: Mike + Copilot | L15: 8-12 | M15: 2.5 | N15: 100% valid state transitions. No orphaned or stuck sessions. | P15: No | Q15: Foundation for the revision loop and WAVE. | R15: Vol III Tools (§III.T9 approval workflow), Vol V (§evaluation lifecycle state machine)
A16: 12 | B16: 3 | C16: 3.2 | D16: Transition Engine | F16: Next | G16: P1 | H16: Prevent invalid state transitions that could corrupt sessions or produce inconsistent outputs. | I16: Validation function that checks current state + requested transition against the allowed transition matrix. Reject and log illegal transitions. | J16: Service layer | K16: Mike + Copilot | L16: 4-6 | M16: 3.1 | N16: 0 illegal transitions in production. All rejections logged. | P16: No | R16: Vol III Ops (§III.O8 state transitions), Vol IV (§governance state lifecycle)
A17: 13 | B17: 3 | C17: 3.3 | D17: Interactive Revision Engine (WAVE) | F17: Planned | G17: P1 | H17: This is where RevisionGrade stops being a diagnostic and becomes a coach. For each flagged issue: show sentence, explain why it's problematic, offer three alternatives + 'edit your own,' accept/reject, progress to closed document state. | I17: Use evaluationresultv1 + WAVE to produce Issue + Suggestion objects per sentence/section. Build a pass UI that iterates issues until no open items remain. Persist versions for before/after comparison (feeds ATI later). | J17: WAVE / Report UI | K17: Mike + Copilot | L17: 16-24 | M17: 2.8 + 3.2 | N17: Full issue iteration. Accept/reject/edit workflow. Document reaches 'closed' state. Version history persisted. | P17: No | Q17: The single most important product differentiator. Depends on credible evaluation AND state machine. | R17: Vol I (62-wave WAVE system, 3 tsunamis, 10 binding execution rules), Vol III (§WAVE enforcement modules)
A18: 14 | B18: 3 | C18: 3.4 | D18: Flexible Upload + Multi-Scope Support | F18: Planned | G18: P1 | H18: Promise is 'anything from a paragraph to a screenplay,' so evaluation + revision flows must treat paragraphs, chapters, full manuscripts, scenes, and screenplays as first-class. | I18: Use worktype/intent pipeline to set expectations and weighting. Reuse evaluation + revision loop; only the view (chapter vs scene vs script format) changes. Auto-chunking and type tagging. | J18: Upload / Evaluation pipeline | K18: Mike + Copilot | L18: 8-12 | M18: 2.8 | N18: All work types (paragraph, chapter, manuscript, scene, screenplay) evaluate and revise correctly. | P18: No | Q18: Backend partially there; needs UX and flow work. | R18: Vol I (§Standard Wave Template, §Velocity Bundle), Vol II-A (§worktype routing)
A19: 15 | B19: 3 | C19: 3.5 | D19: Session Metrics | F19: Planned | G19: P2 | H19: Observability into what's happening inside revision sessions. Without counters and timestamps, you can't diagnose performance or track usage patterns. | I19: Add counters (proposals generated, applied, rejected, failed) + timestamps (created, last_active, closed) to revision_sessions DB fields. | J19: DB fields | K19: Mike + Copilot | L19: 4-6 | M19: 3.1 | N19: Counters match DB rows. Timestamps accurate to second. | P19: No | R19: Vol III Ops (§III.O6 audit logging), Vol V (§V.11 observability)
A20: 16 | B20: 4 | C20: 4.1 | D20: Chapter → Screenplay Conversion | F20: Planned | G20: P2 | H20: Let authors reuse their IP across publishing and film. Increases the value of the evaluation engine by making it a creative tool, not just a diagnostic. | I20: Define explicit conversion rules (sluglines, dialogue extraction, scene boundaries). Treat converted output as a new 'work' that can be evaluated/revised again. | J20: Conversion service | K20: Mike | L20: 10-14 | M20: 3.3 | N20: Converted screenplays pass format validation. Original structure preserved. | P20: No | R20: Vol V (§V.1 certified artifact types — screenplay), Vol I (§Tsunami structure mapping)
A21: 17 | B21: 4 | C21: 4.2 | D21: Manuscript → Full Screenplay | F21: Planned | G21: P2 | H21: Extends chapter conversion to full-manuscript scope. Respects overall narrative structure and act boundaries. | I21: Map manuscript structure (parts, chapters) to screenplay structure (acts, sequences, scenes). Batch conversion with continuity checks. | J21: Conversion service | K21: Mike | L21: 12-16 | M21: 4.1 | N21: Full manuscript converts with correct act structure and scene continuity. | P21: No | R21: Vol V (§V.1 certified artifact types — screenplay), Vol I (§narrative structure mapping)
A22: 18 | B22: 4 | C22: 4.3 | D22: Agent Query Package | F22: Planned | G22: P2 | H22: Bridges the gap from 'good manuscript' to 'submission ready.' Agents care about the package, not just the prose. | I22: From revised work + author resume, generate: author bio, synopsis, pitch, three comps, and query letter. Use evaluationresultv1 + WAVE insights to inform pitch and comps. Editable templates; persist as package artifact. | J22: Export / Package service | K22: Mike | L22: 8-12 | M22: 3.3 | N22: Complete query package generated. All fields editable. Package persisted as artifact. | P22: No | R22: Vol V (§V.1 certified artifact types — submission kit), Vol II-A (§agent-ready WCS ≥8.5)
A23: 19 | B23: 4 | C23: 4.4 | D23: Film Adaptation Package (12-Slide Deck) | F23: Planned | G23: P2 | H23: Gives screenwriters something producers and execs recognize immediately: logline, characters, acts, set pieces, tone, comps. | I23: Define slide schema (12 slides). Map narrative structure + evaluation insights into schema. Generate deck from persisted artifacts. | J23: Export / Deck generation | K23: Mike | L23: 8-12 | M23: 4.2 | N23: 12-slide deck generated with all required sections. Consistent with evaluation data. | P23: No | R23: Vol V (§V.10 certified artifact bundle), Vol II (§13-criteria summary for industry output)
A24: 20 | B24: 5 | C24: 5.1 | D24: Telemetry Dashboard | F24: Planned | G24: P2 | H24: System visibility: you need to see what's happening across all jobs, sessions, and failures before you can scale. | I24: Metrics dashboard in Admin UI. All counters from session metrics queryable. Job state queries, basic SLA alerting. | J24: Admin UI | K24: Mike | L24: 12-16 | M24: 3.5 | N24: All metrics queryable. SLA alerts functional. | P24: No | Q24: Part of Reliability Phase C (D1-D5). | R24: Vol III Ops (§III.O6 analytics dashboard), Vol V (§V.11 health dashboard)
A25: 21 | B25: 5 | C25: 5.2 | D25: UX Flow (Upload → Evaluate → Revise) | F25: Planned | G25: P1 | H25: Usable product: the end-to-end user journey that ties everything together. Without this, RevisionGrade is a backend, not a product. | I25: Next.js flow: upload → evaluate → view report → enter revision → accept/reject → export. Responsive, accessible, clear progress indicators. | J25: Next.js frontend | K25: Mike | L25: 12-20 | M25: 3.3 + 2.6 | N25: End-to-end user flow works. Writer can go from upload to revised document without leaving the app. | P25: No | R25: Vol III Tools (§III.T9 UI components), Vol III Ops (§III.O4 7-stage pipeline UX)
A26: 22 | B26: 5 | C26: 5.3 | D26: Author Work Dashboard | F26: Planned | G26: P2 | H26: Makes the system feel like infrastructure, not a one-off tool. Shows all works with status, scores, history. Supports ATI later. | I26: Use evaluation_jobs + artifacts to build canonical 'work timeline.' Filters by form, status, score band. Reopen capability. | J26: Frontend / DB | K26: Mike | L26: 10-14 | M26: 5.2 | N26: All works listed with status, scores, last opened, history. Filter and reopen working. | P26: No | R26: Vol III Tools (§III.T9 author dashboard), Vol III Ops (§evaluation lifecycle display)
A27: 23 | B27: 5 | C27: 5.4 | D27: Writing-Improvement Analytics (ATI Foundation) | F27: Future | G27: P3 | H27: First visible step toward Author Trajectory Intelligence. Trendlines of problem areas and strengths over time per author. | I27: Compute and persist deltas between evaluations. Visualize per-criterion improvement/regression. Requires multiple evaluations per author. | J27: Analytics / DB | K27: Mike | L27: 10-14 | M27: 5.3 | N27: Trendlines display per-criterion. Deltas computed and persisted. | P27: No | R27: Vol II-A (§score history, criterion deltas), Vol V (§trajectory signals)
A28: 24 | B28: 5 | C28: 5.5 | D28: Trajectory Engine (Score History) | F28: Future | G28: P3 | H28: Track improvement over time. Historical scoring enables the 'signal' that makes StoryGate valuable to agents. | I28: Score history DB. Delta computation. Trend visualization. Feeds into Signal Engine. | J28: DB + logic | K28: Mike | L28: 10-14 | M28: 5.4 | N28: Historical tracking accurate. Trends queryable. | P28: No | R28: Vol V (§trajectory signal computation), Vol II-A (§WCS trending)
A29: 25 | B29: 5 | C29: 5.6 | D29: Agent Report Export | F29: Future | G29: P3 | H29: Market output: agents and publishers expect PDF/DOCX deliverables, not just web views. | I29: PDF/Doc generation from persisted evaluation + revision artifacts. Consistent formatting. Branded templates. | J29: Export service | K29: Mike | L29: 8-12 | M29: 5.2 | N29: Reports consistent, branded, and usable in agent submissions. | P29: No | R29: Vol V (§V.1 5 certified external artifacts, §V.10 non-repudiation), Vol III Ops (§III.O4 Stage 6-7 export)
A30: 26 | B30: 5 | C30: 5.7 | D30: Signal Engine (Predictive Scoring) | F30: Future | G30: P3 | H30: Predict outcomes: given evaluation data + trajectory, estimate likelihood of agent interest, publication readiness, or film viability. | I30: Probability model built on evaluation criteria, trajectory deltas, and (eventually) marketplace engagement data. | J30: Scoring model | K30: Mike | L30: 12-18 | M30: 5.5 | N30: Prediction aligns with known outcomes in test corpus. | P30: No | R30: Vol V (§Trifecta Model), Vol II-A (§agent-ready threshold 8.5, §market trigger 6.0)
A31: 27 | B31: 5 | C31: 5.8 | D31: StoryGate Studio Marketplace | F31: Future | G31: P3 | H31: Public landing where works scoring ≥8 post automatically as 'black premium marketing' tied to author profiles. Solves slush by ensuring agents only see vetted material. | I31: Gating rule on evaluation results. Publish metadata (title, genre, logline, score band) — not full manuscripts. Author profiles linked. | J31: Web app / Public | K31: Mike + Future team | L31: 20-30 | M31: 5.5 + 5.6 | N31: Qualifying works auto-posted. Metadata-only exposure. Author profiles functional. | P31: No | Q31: Gate 8+ concept. | R31: Vol V (§V.10 Trusted Path certification), Vol III Governance (§visibility states)
A32: 28 | B32: 5 | C32: 5.9 | D32: Agent Portal & Connection Economics | F32: Future | G32: P3 | H32: Second side of the marketplace and core revenue stream. Agents browse StoryGate by genre, score band, form, history. Brokered introductions generate revenue. | I32: Role-based access. Visibility states (private / agent-beta / public). Track views, saves, introductions as first-class events. Agent application and approval flow. | J32: Web app / Admin | K32: Mike + Future team | L32: 20-30 | M32: 5.8 | N32: Agents can browse, filter, request introductions. Event tracking live. | P32: No | R32: Vol V (§V.10 industry interface), Vol III Governance (§role-based access)
A33: 29 | B33: 5 | C33: 5.10 | D33: Stripe Billing + Connection Fees | F33: Future | G33: P3 | H33: Revenue infrastructure: paid usage for RevisionGrade plus transaction fees for author-agent matches. | I33: Stripe integration: plans, metering, connection events, reconciliation. Separate project. | J33: Billing service | K33: Mike + Future team | L33: 16-24 | M33: 5.9 | N33: Billing functional. Connection fees tracked and reconciled. | P33: No | Q33: Not yet initiated. | R33: Vol V (§connection economics), Vol III Ops (§transaction tracking)
A34: 30 | B34: 5 | C34: 5.11 | D34: Observability, SLAs & Dead-Letter | F34: Future | G34: P3 | H34: System-health dashboards, job state queries, SLA alerting, dead-letter queues. Required for production reliability at scale. | I34: Implement Phase C D1-D5: failure envelope, structured logs, observability queries, dead-letter, health dashboard. | J34: Infrastructure | K34: Mike | L34: 12-16 | M34: 5.1 | N34: All health metrics live. Dead-letter queue functional. SLA alerting active. | P34: No | Q34: Reliability Phase C artifacts. | R34: Vol V (§V.11 full reliability model: dead-letter, retry, degraded mode, incident), Vol III Ops (§III.O6, §III.O8)
A35: 31 | B35: 5 | C35: 5.12 | D35: QA Corpus (300 Varied Samples) | F35: Future | G35: P3 | H35: De-risks bias, inconsistency, and failure modes before scale. Validates scoring + suggestions across forms, genres, and difficulty. | I35: Build harness that runs full evaluation + revision loop on 300-sample corpus. Check for regressions. Automated CI integration. | J35: Test infrastructure | K35: Mike | L35: 16-24 | M35: 3.3 + 2.8 | N35: Full corpus evaluated without regressions. Bias and consistency metrics within thresholds. | P35: No | R35: Vol II (13 criteria × genres × difficulty), Canon III Lesson I:5 (adversarial testing requirement)
A36: 32 | B36: 2 | C36: 2.9 | D36: Canon Gate (Pass 1.5) Schema Validator | F36: Planned | G36: P1 | H36: Vol III mandates: Canon Gate must execute before results surface to users — always. Pass 1.5 validates evaluation output against canonical schema before persistence. Without this, malformed evaluations can poison the artifact store. | I36: Build schema validator that checks EvaluationResultV1 output against canonical schema. Hard fail on: missing criteria, out-of-range scores, missing evidence. Soft fail on: short recommendations (<50 chars), low confidence (<0.5). Max 3 retries, 60s timeout. | J36: lib/validation/canonGate.ts | K36: Mike + Copilot | L36: 6-8 | M36: 2.7 | N36: 100% of evaluations pass through Canon Gate before persistence. 0 malformed evaluations in artifact store. Hard/soft fail classification correct. | O36: Feed 20 valid and 20 malformed evaluations. All valid pass, all malformed rejected with correct fail type. | P36: Yes | Q36: Non-negotiable governance requirement. Pass 1.5 sits between evaluation and persistence. | R36: Vol III Tools (§III.T6 Canon Gate), Vol III Ops (§Canon Gate hard fail retries: 3, timeout: 60s)
A37: 33 | B37: 2 | C37: 2.10 | D37: Two-AI Pipeline Contract (Independence Guarantee) | F37: Planned | G37: P1 | H37: Vol II-A and Vol IV mandate a minimum two-AI evaluation pipeline. Pass 2 must NEVER receive Pass 1 outputs — independence is absolute. Single-pass evaluation cannot distinguish 'confident agreement' from 'confident but wrong.' | I37: Implement System 1 (generate) → System 2 (audit) pipeline. Pass 2 receives only the original manuscript + criteria, never Pass 1 results. Log divergence to audit envelope. Convergence logic: majority_vote / weighted_merge / consensus / authority_override. | J37: lib/evaluation/pipeline/ | K37: Mike + Copilot | L37: 12-16 | M37: 2.7 + 2.9 | N37: Pass 2 provably independent (no data path from Pass 1 output to Pass 2 input). Divergence logged. Convergence method selected and justified per evaluation. | O37: Inject known divergent evaluations. Verify: divergence logged, convergence method applied correctly, no Pass 1 leakage into Pass 2 context. | P37: Yes | Q37: Minor disagreement: ±10 points (auto-resolve). Major disagreement: ±20 points (human review trigger). Vol IV §IV.G4.3. | R37: Vol II-A (§two-AI contract), Vol III Tools (§III.T4, §III.T5 PASS1/PASS2/PASS3), Vol IV (§multi-AI consensus, ±5 agreement threshold)
A38: 34 | B38: 2 | C38: 2.11 | D38: Provider-Agnostic Adapter Layer | F38: Planned | G38: P2 | H38: Vol III Tools mandates: core logic must NEVER call provider APIs directly — adapters only. This is a non-negotiable architecture rule that enables provider switching, testing, and degraded-mode operation. | I38: Implement ModelAdapter TypeScript interface. Build OpenAI adapter + Anthropic adapter. All evaluation pipeline calls go through adapter layer. Prompts loaded at runtime from files (aep-pass1.txt, aep-pass2.txt, aep-pass3.txt), never hardcoded. | J38: lib/adapters/ | K38: Mike + Copilot | L38: 8-10 | M38: 2.10 | N38: 0 direct provider API calls in evaluation pipeline. All calls through adapter. Prompts loaded from filesystem at runtime. Provider can be swapped by config change. | O38: grep codebase for direct OpenAI/Anthropic imports in evaluation logic — must be 0. Swap adapter config, verify evaluation still runs. | P38: No | Q38: Temperature settings per canon: PASS1/PASS2 = 0.3, PASS3 = 0.2. Max tokens: PASS1/PASS2 = 4000, PASS3 = 5000. | R38: Vol III Tools (§III.T7 ModelAdapter interface, §III.T11 adapters), Vol V (§V.6 degraded mode)
A39: 35 | B39: 3 | C39: 3.6 | D39: WAVE Enforcement Modules | F39: Planned | G39: P2 | H39: Vol III Governance and Vol IV require 4 WAVE enforcement modules that gate revision quality. Structural failure must block cosmetic polish tools — no exceptions in Trusted Path. | I39: Build 4 modules: (1) Structural integrity gate, (2) Criterion-to-WAVE routing (Vol II-A mapping), (3) Tsunami sequencing enforcer (Structural Truth → Reader Momentum → Literary Authority), (4) Velocity Bundle eligibility checker (all criteria ≥7.0). | J39: lib/wave/enforcement/ | K39: Mike + Copilot | L39: 10-14 | M39: 3.3 | N39: Structural criterion <5 blocks WAVE entry. Waves execute in correct tsunami order. Velocity Bundle only available when all criteria ≥7.0. | O39: Submit manuscript with structural criterion at 4 — WAVE blocked. Submit with all criteria ≥7.0 — Velocity Bundle available. Submit with mixed scores — correct routing only. | P39: No | Q39: 62 waves across 3 tsunamis. 10 binding execution rules from Vol I. | R39: Vol III Governance (§4 WAVE enforcement), Vol IV (§IV.G3 canon protection), Vol I (62 waves, 3 tsunamis, Velocity Bundle rules)
A40: 36 | B40: 3 | C40: 3.7 | D40: Eligibility Gate System | F40: Planned | G40: P1 | H40: Vol II-A defines hard eligibility gates that determine what the system offers a writer. These aren't soft suggestions — they're structural blocks. WCS <7.0 means no WAVE. Structural criterion <5 means hard block. Agent-ready requires ≥8.5. | I40: Implement gate logic: FOUNDATIONAL (<60) → DEVELOPING (60-64) → REFINEMENT_ELIGIBLE (65-79) → AGENT_READY (≥80). Hard block on WAVE when any structural criterion <5 OR WCS <7.0. Map gates to UI states and available features. | J40: lib/evaluation/gates/ | K40: Mike + Copilot | L40: 6-8 | M40: 2.6 + 2.9 | N40: All 4 readiness states correctly assigned. Hard blocks enforced. No WAVE access below threshold. Agent-ready threshold at ≥8.5 (mapped to ≥80 on 100-point scale). | O40: Submit manuscripts at each threshold boundary (49/50, 59/60, 64/65, 79/80, 84/85). Verify correct state assignment and feature gating at each. | P40: Yes | Q40: Score scale: 1-10 integer (half-points disallowed per Vol II-A). WCS weights defined in Vol II-A criterion registry. | R40: Vol II-A (§eligibility gates: WCS 7.0, structural 5, agent-ready 8.5, market trigger 6.0), Vol III Ops (§thresholds 50/60/65/80)
...

Sheet Sprint 0 (Phase 2)
A1: Sprint | B1: Phase_ID | C1: Task_Group | D1: Subtask_ID | E1: Subtask | F1: Type | G1: Where (Codebase) | H1: Success Criteria | I1: Test Method | J1: Output Artifact | K1: Status
A2: PHASE 0 | B2: Canon Integration & Authority Enforcement | C2: Bind canon registry, lessons learned, and governance into runtime enforcement layer | D2: Required before Phase 2.2
A3: 0.1 | B3: Canon Registry Binding | C3: Map Vol I–V, Doctrine Registry, Lessons Learned into canonical IDs + precedence
A4: 0.2 | B4: Lessons → Rules Mapping | C4: Convert lessons learned into validation rules (blur, authority transfer, stalled scenes)
A5: 0.3 | B5: Canon Guard Runtime | C5: Fail execution if output violates canon (no silent pass)
A6: 0.4 | B6: Audit Layer | C6: Produce canon compliance report per run
A7: S0-Apply-Engine | B7: 2.1 | C7: Anchor Metadata System | D7: 2.1.a | E7: Complete | F7: Design | G7: DB / Schema | H7: Schema defines start_offset (int), end_offset (int), before_context + after_context (strings, ~40 chars each). All fields required, non-nullable. | I7: Schema review + Zod parse test: feed 10 valid and 10 malformed anchors. 100% correct accept/reject. | J7: docs/schemas/anchor-metadata.md + Zod schema file (lib/types/anchor.ts)
A8: S0-Apply-Engine | B8: 2.1 | C8: Anchor Metadata System | D8: 2.1.b | E8: Complete | F8: DB Migration | G8: supabase/migrations | H8: Migration runs clean on empty and populated DB. change_proposals table has start_offset, end_offset, before_context/after_context columns. Rollback succeeds without data loss. | I8: supabase db reset + migrate up + migrate down. Verify columns exist via SQL introspection. Insert test row, rollback, confirm no orphan data. | J8: supabase/migrations/<timestamp>_add_anchor_fields.sql + migration test log
A9: S0-Apply-Engine | B9: 2.1 | C9: Anchor Metadata System | D9: 2.1.c | E9: Complete | F9: Backend | G9: lib/db/, lib/types/ | H9: TS types and Zod validators match DB schema exactly. All proposal CRUD operations enforce anchor fields. No untyped access to anchor data anywhere in codebase. | I9: TypeScript strict compile (0 errors). Zod .parse() on 20 sample proposals (10 valid, 10 invalid). grep codebase for raw SQL accessing anchor columns — must be 0. | J9: lib/types/proposal.ts + lib/db/proposals.ts (updated) + TS compile log
A10: S0-Apply-Engine | B10: 2.1 | C10: Anchor Metadata System | D10: 2.1.d | E10: Complete | F10: Validation / Tests | G10: lib/validation/, tests/anchors/ | H10: 100% of proposals in test corpus have valid anchors. 0 proposals accepted with null/empty start_offset, end_offset, or before_context/after_context. Validation rejects malformed anchors at insert time. | I10: Run full proposal generation pipeline on 3 sample manuscripts. Query: SELECT COUNT(*) FROM change_proposals WHERE start_offset IS NULL OR end_offset IS NULL — must return 0. Attempt 5 invalid inserts — all rejected. | J10: tests/anchors/anchor-validation.test.ts + test run report (pass/fail counts)
A11: S0-Apply-Engine | B11: 2.2 | C11: Proposal Extraction | D11: 2.2.a | E11: Define extraction contract | F11: Design | G11: docs/contracts/, schemas/ | H11: Contract document specifies: input format, output schema, whitespace handling rules, partial-capture rejection criteria, edge cases (unicode, line breaks, tabs). Reviewed and signed off. | I11: Peer review: walk through 5 edge-case examples against the contract. Each example must have a deterministic expected output documented. | J11: docs/contracts/extraction-contract.md + 5 edge-case examples in docs/contracts/extraction-examples.md
A12: S0-Apply-Engine | B12: 2.2 | C12: Proposal Extraction | D12: 2.2.b | E12: Implement extraction logic (0 whitespace drift) | F12: Backend | G12: lib/evaluation/proposals/ | H12: 0 whitespace drift: extracted anchor text matches source text byte-for-byte. 0 partial captures: every extraction includes complete sentence/clause boundaries. Handles unicode, em-dashes, smart quotes. | I12: Run extraction on 50+ proposals from 3 different manuscripts. Diff each extracted anchor against source text — 0 byte-level differences. Flag any extraction that splits mid-word or mid-clause. | J12: lib/evaluation/proposals/extractProposals.ts + extraction diff report (CSV: proposal_id, source_text, extracted_text, match_status)
A13: S0-Apply-Engine | B13: 2.2 | C13: Proposal Extraction | D13: 2.2.c | E13: Add tests for 0 drift / partial captures | F13: Tests | G13: tests/proposals/ | H13: Test suite covers: exact match, whitespace variants (tabs, double spaces, newlines), unicode (em-dash, curly quotes, accented chars), partial capture rejection, empty input, overlapping anchors. | I13: Run test suite: 100% pass. Coverage report shows ≥95% line coverage on extraction logic. Add regression test for every bug found during development. | J13: tests/proposals/extraction.test.ts + coverage report (HTML or lcov)
A14: S0-Apply-Engine | B14: 2.3 | C14: Location-Aware Apply | D14: 2.3.a | E14: Design apply algorithm (offset + context + fallback) | F14: Design | G14: docs/algorithms/apply.md | H14: Algorithm doc specifies: primary match (offset), fallback match (context window ±N chars), conflict resolution (overlapping edits), idempotency guarantee. Pseudocode for each path. | I14: Walk through 10 scenarios on paper: exact match, offset shifted by edit, context fallback, overlapping proposals, duplicate apply. Each scenario has expected outcome documented. | J14: docs/algorithms/apply.md (with pseudocode + 10 scenario walkthroughs)
A15: S0-Apply-Engine | B15: 2.3 | C15: Location-Aware Apply | D15: 2.3.b | E15: Implement deterministic apply function | F15: Backend | G15: lib/revision/applyEngine.ts | H15: ≥99.5% correct placement on valid anchors. 0 incorrect edits (wrong location = critical failure). Idempotent: applying same proposal twice produces identical output. Handles multi-byte unicode correctly. | I15: Run 500-1000 proposals through apply engine. Diff original vs applied at character level. Rerun identical batch — output must be byte-identical. Test with unicode-heavy manuscript (Spanish, accented chars). | J15: lib/revision/applyEngine.ts + test log (pass/fail counts, placement accuracy %, idempotency check result)
A16: S0-Apply-Engine | B16: 2.3 | C16: Location-Aware Apply | D16: 2.3.c | E16: Harness tests for ≥99.5% success | F16: Tests / Harness | G16: tests/applyEngine/ | H16: Harness covers: exact offset match, context-fallback match, overlapping proposals, sequential multi-apply, idempotent rerun, unicode edge cases, empty proposal, proposal on deleted text. | I16: Automated harness: run full suite, report per-scenario pass/fail. ≥99.5% overall. 0 incorrect placements. Harness runs in CI (< 60s). Add regression test for every production failure. | J16: tests/applyEngine/ (full harness) + CI integration (.github/workflows/) + harness summary report
A17: S0-Apply-Engine | B17: 2.4 | C17: Failure Classification | D17: 2.4.a | E17: Enumerate failure codes | F17: Design | G17: docs/errors/, lib/errors/revisionCodes.ts | H17: Closed set of failure codes (ANCHOR_MISS, CONFLICT, PARSE_ERROR, INVARIANT_VIOLATION). No UNKNOWN or empty types. | I17: Review code for any untyped throw/catch. Grep for unknown failure strings. | J17: lib/errors/revisionCodes.ts, PACK_F_EXECUTION_CONTRACT.md
A18: S0-Apply-Engine | B18: 2.4 | C18: Failure Classification | D18: 2.4.b | E18: Wire codes into revision_sessions + telemetry | F18: Backend / DB | G18: supabase/migrations, lib/db/revisionSessions.ts, lib/revision/telemetry.ts | H18: Every failed apply stores a specific failure code + context. Telemetry event codes cover all apply paths. | I18: Run all apply paths (valid, invalid offsets, overlap, stale anchor). Verify DB row has non-null failure_code. | J18: Updated revision_sessions schema, telemetry.ts event codes
A19: S0-Apply-Engine | B19: 2.4 | C19: Failure Classification | D19: 2.4.c | E19: Tests: 100% classified failures + Pack F soak qualification | F19: Tests / Harness | G19: tests/failures/, tests/operations/, scripts/soak/ | H19: 10 suites/100 tests green. Pack F 100k soak: 0 unclassified, 0 wrong-location, 0 lost writes. | I19: npm test (full suite). npm run soak:run with 1k/10k/100k events. Verify archived evidence ladder. | J19: soak-harness.test.ts, packF archives (1k/10k/100k)
A20: S0-Apply-Engine | B20: 2.5 | C20: Stage Validation | D20: 2.5.a | E20: Build deterministic stage-validation e2e harness | F20: Tests / Harness | G20: tests/anchors/stage-validation-e2e.test.ts | H20: 5 success cases + 3 failure cases. 9/9 ingest, 9/9 extract, 9/9 validate, 9/9 apply. All pass. | I20: npm test -- tests/anchors/stage-validation-e2e.test.ts. Verify JSON: pass=true. | J20: stage-validation-e2e.test.ts, pack25 JSON/MD reports
A21: S0-Apply-Engine | B21: 2.5 | C21: Stage Validation | D21: 2.5.b | E21: Repeated-run byte identity proof + evidence archival | F21: Tests / Evidence | G21: docs/operations/evidence/runs/ | H21: repeated_run_identity_passed=true for all cases. Pipeline-identity byte-identical across runs. 3 evidence runs archived. | I21: Run harness with PACK_25_REPORT_DIR. Verify JSON: repeated_run_identity_passed=true. | J21: 3 archived evidence directories under docs/operations/evidence/runs/
A22: S0-Apply-Engine | B22: 2.6 | C22: A6 Report Credibility | D22: 2.6.a | E22: Build A6 report: types, buildA6Report, confidence, provenance, validateA6Report, writeA6Artifacts | F22: Backend | G22: lib/evaluation/a6/ | H22: buildA6Report produces valid rubric + confidence + provenance; validateA6Report enforces invariants | I22: 4 unit tests in a6-report-credibility.test.ts (rubric, missing-refs, phantom-anchor, confidence-richness) | J22: lib/evaluation/a6/*.ts (6 modules), a6_report.json, a6_validation_summary.json
A23: S0-Apply-Engine | B23: 2.6 | C23: A6 Report Credibility | D23: 2.6.b | E23: Evidence run + artifact output (JSON+MD) + validation summary | F23: Tests / Evidence | G23: scripts/a6/, tests/evaluation/, docs/operations/evidence/runs/ | H23: Evidence artifacts generated, all invariants pass, failure cases (missing-refs, phantom-anchor) tested | I23: a6-artifact-output.test.ts (JSON+MD write) + run-a6-evidence.ts execution | J23: a6_report.json, a6_report.md, a6_validation_summary.json, metadata.json
A24: S0-Apply-Engine | B24: 2.6 | C24: A6 Report Credibility | D24: 2.6.c | E24: Closure documentation + offset audit + ChatGPT verification | F24: Governance | G24: PHASE_2_6_A6_REPORT_CREDIBILITY_CLOSURE.md | H24: Closure doc populated (214 lines, 7559 bytes on main), spec compliance verified, offset consistency confirmed [43,86) | I24: Manual review: closure doc completeness, offset consistency, 5/5 tests green post-fix (38d9c19) | J24: PHASE_2_6_A6_REPORT_CREDIBILITY_CLOSURE.md (landed on main at 66b84e4, 214 lines)
A25: EXECUTION GOVERNANCE NOTES
A26: Current State | B26: Roadmap (strategic) + Sprint (operational) + Verification (truth). Three-layer execution structure.
A27: Core Principle | B27: Eliminate "I think this is done." Replace with "This passed its defined success test." Every row has provable completion.
A28: Critical Path | B28: 2.1 → 2.2 → 2.3 → 2.4. Do NOT parallelize. Each depends on the prior being VERIFIED, not just coded.
A29: 2.3 Is The Product | B29: The apply engine is the product. Everything else — UI, reports, packaging — is presentation. If 2.3 is deterministic, idempotent, and precise, you win. If not, everything collapses.
A30: When 2.3 Fails | B30: Do NOT patch. Do NOT add hacks. Log everything → classify failures (2.4) → refine determinism. This is the discipline that separates a system from a tool.
A31: Scope Discipline | B31: Do NOT expand scope. Do NOT add features. Finish 2.1 VERIFIED → 2.2 VERIFIED → 2.3 VERIFIED → 2.4 VERIFIED. Then and only then move forward.
A32: 2.1 VERIFIED (2026-03-18). Code complete + tests pass + DB verification 6/6 gates passed on target DB. 21 anchored rows verified — deterministic slice contract holds. Data remediation: 2 manuscript_versions backfilled (raw_text from file_url), 15 anchor offsets recomputed. GATE CLEARED → 2.2 may proceed. | B32: 2.1 CODE COMPLETE + TEST VERIFIED. DB rollout pending. SQL verification pack created (phase21-db-verification.sql). Runbook at tests/anchors/PHASE21_DB_VERIFICATION_RUNBOOK.md. GATE: DB verification must pass before 2.2 begins.
A33: 0 | B33: 2.7 | C33: Pipeline Scaffold | D33: 2.7.a | E33: Pass 1/2/3 runners + prompt templates + types | F33: Code | G33: lib/evaluation/pipeline/ | H33: runPass1, runPass2, runPass3Synthesis exported and callable with DI seam | I33: pass1.test.ts, pass2.test.ts, pass3.test.ts — pure parser + DI runner tests | J33: 9 lib files: runPass1.ts, runPass2.ts, runPass3Synthesis.ts, runPipeline.ts, qualityGate.ts, types.ts, 3 prompt files | K33: Complete
A34: 0 | B34: 2.7 | C34: Pipeline Scaffold | D34: 2.7.b | E34: Quality gate (10 deterministic checks, no AI) | F34: Code | G34: lib/evaluation/pipeline/qualityGate.ts | H34: All 10 QG checks pass on valid synthesis, fail on invalid. No AI calls. | I34: quality-gate.test.ts — 15 tests covering all error codes | J34: qualityGate.ts (214 lines), quality-gate.test.ts (345 lines) | K34: Complete
A35: 0 | B35: 2.7 | C35: Pipeline Scaffold | D35: 2.7.c | E35: Pipeline orchestrator + EvaluationResultV1 adapter | F35: Code | G35: lib/evaluation/pipeline/runPipeline.ts | H35: runPipeline orchestrates Pass 1→2→3→4, returns PipelineResult union. synthesisToEvaluationResult maps to V1 schema. | I35: pipeline-e2e.test.ts (7 tests), pipeline-independence.test.ts (4 tests) | J35: runPipeline.ts (241 lines) with _runners DI seam | K35: Complete
A36: 0 | B36: 2.7 | C36: Test Harness | D36: 2.7.d | E36: Jest/SWC mock-hoisting fix — DI refactor, zero jest.mock | F36: Test | G36: tests/evaluation/pipeline/ | H36: 52/52 tests pass. Zero jest.mock calls. Pure parser tests + DI runner injection. | I36: npm test -- tests/evaluation/pipeline/ --runInBand → 6 suites, 52 tests, all green | J36: 6 test files, 52 tests. Commits: a6f0492, 9ef8afe, c91f26c | K36: Complete
A37: 0 | B37: 2.7 | C37: Pipeline Hardening | D37: 2.7.e | E37: Model override threading — end-to-end configurable model per pipeline run | F37: Code | G37: lib/evaluation/pipeline/*.ts | H37: model?: string threaded through runPass1/2/3 + runPipeline. Tested in pass1.test.ts + pipeline-e2e.test.ts | K37: Complete
A38: 0 | B38: 2.7 | C38: Pipeline Hardening | D38: 2.7.f | E38: Real-run CLI upgrade — artifact emission (raw, parsed, usage, quality gate) | F38: Code | G38: scripts/pipeline/run-phase2-7-real-run.ts | H38: CLI accepts --input/--title/--work-type/--model/--output-dir. Emits full artifact set. | K38: Complete
A39: 0 | B39: 2.7 | C39: Evidence & Closure | D39: 2.7.g | E39: Fresh live evidence run — full artifact set with upgraded pipeline | F39: Evidence | G39: docs/operations/evidence/runs/ | H39: quality_gate.json + pipeline_result.json + usage.json all present. Independence gate passes. | K39: Blocked (OPENAI_API_KEY)
A40: 0 | B40: 2.7 | C40: Evidence & Closure | D40: 2.7.h | E40: Independence gate calibration — exclude manuscript-sourced phrases from n-gram check | F40: Code | G40: lib/evaluation/pipeline/qualityGate.ts | H40: Independence check no longer flags natural language convergence. Only flags actual pass-to-pass leakage. | K40: Complete
...

Sheet Immediate Priorities
B2: Immediate Priorities — The Next Three
B3: Once these three are real, everything else sits on a foundation that feels like a senior editor, not a rubric engine.
B5: # | C5: Deliverable | D5: Status | E5: Depends On | F5: What | G5: Why | H5: How | I5: Done When | J5: LOE
B6: 1 | C6: Close A6 — Report Credibility Layer | D6: Next (start immediately) | E6: Gate A5 (completed) | F6: Lock in score explanations, rubric mapping, confidence levels, and provenance on the existing report. All driven from persisted artifacts — zero recomputation. | G6: A writer who sees '8.3' without understanding why will never trust the system enough to pay for revision or packaging. Credibility is the unlock for everything downstream. | H6: Extend evaluationresultv1 content block with rubric items and credibility metadata. Render 'Why this score?' section in report UI. Artifact-only reads. | I6: Rubric breakdown, score explanations, confidence, and provenance all visible. Report loads from artifact with zero recomputation. | J6: 6-8 hours
B7: 2 | C7: Evaluation Uplift — Pass 1-4, Quality Guards, Dual Axis | D7: Next (after A6) | E7: A6 Report Credibility | F7: Dual-axis evaluation: Craft Execution + Editorial/Literary Insight. Multi-pass pipeline (structural → intent/genre → interpretive → synthesis) with quality guards. | G7: This is the psychological shift from 'grader' to 'trusted editor.' It drives repeat use, justifies pricing, and makes the trajectory + packaging products meaningful. | H7: Four-pass pipeline. Guards before persistence: no duplicated recs vs summary, no generic recs (must anchor to character/scene/event), no pretending full coverage when partial. Multi-chunk correctness. | I7: Dual-axis scores rendered. Zero generic recommendations. All recs anchored to specific text. Multi-chunk synthesis with 100% coverage or explicit partial labeling. | J7: 22-30 hours (includes 2.7 + 2.8)
B8: 3 | C8: Interactive Revision Loop (WAVE) | D8: Planned (after uplift) | E8: Evaluation Uplift + State Machine + Transition Engine | F8: For each flagged issue: show sentence, explain why problematic, offer 3 alternatives + 'edit your own,' accept/reject with progression to 'closed' document state. | G8: This is where RevisionGrade stops being a diagnostic and becomes a coach. It's the product differentiator and the scaffolding for trajectory intelligence. | H8: evaluationresultv1 + WAVE → Issue + Suggestion objects per sentence/section. Pass UI iterates issues until none remain. Persist versions for before/after ATI comparison. | I8: Full issue iteration works. Accept/reject/edit workflow functional. Document reaches 'closed' state. Version history persisted. | J8: 16-24 hours
B11: ← Back to Overview

Sheet Canon Reference
B2: RevisionGrade — Canon Document Reference
B3: Mapping between 5-volume governance canon and roadmap execution items
B5: CANON AUTHORITY CHAIN
B6: Canon III — Meta-Governance (DOMINATUS) | C6: 8 governing laws. Adversarial testing required. No silent changes.
B7: → Volume IV — AI Governance Canon | C7: 3-layer authority model. 7 canon protection systems. 4 violation severity levels. Human review at ±20 points.
B8: → Canon Doctrine Registry | C8: 77 canonical doctrine units. Single source of truth. 6 registry governance rules.
B9: → Canon Assembly Matrix (RCAM v2.0) | C9: 24 source documents mapped to 5 volumes. 5 matrix rules. Build map.
B10: → Volume II — Story Evaluation Canon | C10: 13 criteria. 10 diagnostic patterns. Scoring doctrine. Evidence trail.
B11: → Volume II-A — Operational Schema | C11: Machine spec. Criterion weights. WCS computation. Eligibility gates. JSON schema. Supabase tables.
B12: → Volume I — WAVE Revision Canon | C12: 62 waves. 3 tsunamis. 10 binding execution rules. Standard Wave Template. Velocity Bundle.
B13: → Volume III — Platform Governance + Tools + Ops | C13: 3 shells: WHY (doctrine) / HOW (schemas, prompts, adapters) / WHEN (thresholds, routing, pipeline).
B14: → Volume V — Execution Architecture | C14: AEP 6-step flow. Trifecta Model. Chunking. Reliability. 5 certified artifact types. 12-step build sequence.
B17: KEY NUMERIC CONSTANTS (Engineering Specs)
B18: Constant | C18: Value | D18: Source
B19: WAVE eligibility minimum WCS | C19: 7.0 | D19: Vol II-A
B20: Structural fail threshold (per criterion) | C20: 5 | D20: Vol II-A
B21: Agent-ready WCS | C21: 8.5 | D21: Vol II-A
B22: Market review trigger | C22: 6.0 | D22: Vol II-A
B23: Score scale | C23: 1-10 integer (no half-points) | D23: Vol II-A
B24: Readiness: FOUNDATIONAL | C24: <60 (100-pt scale) | D24: Vol III Ops
B25: Readiness: DEVELOPING | C25: 60-64 | D25: Vol III Ops
B26: Readiness: REFINEMENT_ELIGIBLE | C26: 65-79 | D26: Vol III Ops
B27: Readiness: AGENT_READY | C27: ≥80 | D27: Vol III Ops
B28: PASS1/PASS2 temperature | C28: 0.3 | D28: Vol III Tools
B29: PASS3 temperature | C29: 0.2 | D29: Vol III Tools
... B47: AI systems in pipeline (minimum) | C47: 2 | D47: Vol II-A
B50: NON-NEGOTIABLE GOVERNANCE RULES
B51: 1. | C51: Structural failure must block cosmetic polish tools — no exceptions in Trusted Path
B52: 2. | C52: Canon Gate (Pass 1.5) must execute before results surface to users — always
B53: 3. | C53: Pass 2 must never receive Pass 1 outputs — independence guarantee is absolute
B54: 4. | C54: Prompts must be loaded at runtime — never hardcoded
B55: 5. | C55: Core logic must never call provider APIs directly — adapters only
B56: 6. | C56: Audit logs are append-only and hash-chained — no DELETE or UPDATE permitted
